Workbook

Sheet Dashboard
B2: AI IMPLOSION DASHBOARD
B3: Built by KK Reddy
B4: ="Equity, AI-financing & credit stress (9 indicators) | Data as of "&TEXT(MAX(tblHistory[Date]),"dd-mmm-yyyy")
B7: STRESS SCORE | D7: STATUS | F7: TRIGGERS | H7: CURRENT LEVEL | J7: L4 FIRST DATE
B8: =Tracker!C5 | D8: =Tracker!C7 | F8: =Tracker!C6 | H8: =Tracker!C17 | J8: =IF(Tracker!C18="","None yet",TEXT(Tracker!C18,"dd-mmm-yyyy"))
B9: ="out of 100" | D9: ="Score band" | F9: ="factors at stress 100%" | H9: ="5 straight days rule" | J9: ="first L4 streak"
B11: FACTOR DETAIL
B12: Metric | C12: Weight | D12: 2Y High (spreads: 52W Low) | E12: Current | F12: Drawdown (spreads: +bp vs low) | G12: Calm | H12: Trigger | I12: Trigger price (HY: band) | J12: Stress | K12: Status | L12: Widen calm (+bp) | M12: Widen trigger (+bp)
B13: Nasdaq-100 (NDX) | C13: 0.18 | D13: =_xlfn.MAXIFS(tblHistory[NDX],tblHistory[Date],"<="&MAX(tblHistory[Date]),tblHistory[Date],">="&MAX(tblHistory[Date])-730) | E13: =SUMIFS(tblHistory[NDX],tblHistory[Date],_xlfn.MAXIFS(tblHistory[Date],tblHistory[NDX],"<>")) | F13: =E13/D13-1 | G13: -0.05 | H13: -0.25 | I13: =D13*(1+H13) | J13: =MIN(1,MAX(0,(F13-G13)/(H13-G13))) | K13: =IF(J13=1,"TRIGGERED",IF(J13>=0.5,"WARNING",IF(J13>0,"WATCH","CALM")))
B14: Semiconductors (SOX) | C14: 0.18 | D14: =_xlfn.MAXIFS(tblHistory[SOX],tblHistory[Date],"<="&MAX(tblHistory[Date]),tblHistory[Date],">="&MAX(tblHistory[Date])-730) | E14: =SUMIFS(tblHistory[SOX],tblHistory[Date],_xlfn.MAXIFS(tblHistory[Date],tblHistory[SOX],"<>")) | F14: =E14/D14-1 | G14: -0.1 | H14: -0.4 | I14: =D14*(1+H14) | J14: =MIN(1,MAX(0,(F14-G14)/(H14-G14))) | K14: =IF(J14=1,"TRIGGERED",IF(J14>=0.5,"WARNING",IF(J14>0,"WATCH","CALM")))
B15: AI & tech ETF (AIQ) | C15: 0.09 | D15: =_xlfn.MAXIFS(tblHistory[AIQ],tblHistory[Date],"<="&MAX(tblHistory[Date]),tblHistory[Date],">="&MAX(tblHistory[Date])-730) | E15: =SUMIFS(tblHistory[AIQ],tblHistory[Date],_xlfn.MAXIFS(tblHistory[Date],tblHistory[AIQ],"<>")) | F15: =E15/D15-1 | G15: -0.05 | H15: -0.3 | I15: =D15*(1+H15) | J15: =MIN(1,MAX(0,(F15-G15)/(H15-G15))) | K15: =IF(J15=1,"TRIGGERED",IF(J15>=0.5,"WARNING",IF(J15>0,"WATCH","CALM")))
B16: Data-center infrastructure ETF (DTCR) | C16: 0.06 | D16: =_xlfn.MAXIFS(tblHistory[DTCR],tblHistory[Date],"<="&MAX(tblHistory[Date]),tblHistory[Date],">="&MAX(tblHistory[Date])-730) | E16: =SUMIFS(tblHistory[DTCR],tblHistory[Date],_xlfn.MAXIFS(tblHistory[Date],tblHistory[DTCR],"<>")) | F16: =E16/D16-1 | G16: -0.1 | H16: -0.35 | I16: =D16*(1+H16) | J16: =MIN(1,MAX(0,(F16-G16)/(H16-G16))) | K16: =IF(J16=1,"TRIGGERED",IF(J16>=0.5,"WARNING",IF(J16>0,"WATCH","CALM")))
B17: BBB corporate spread (bp) (BBB) | C17: 0.06 | D17: =_xlfn.MINIFS(tblHistory[BBB],tblHistory[Date],"<="&MAX(tblHistory[Date]),tblHistory[Date],">="&MAX(tblHistory[Date])-365) | E17: =SUMIFS(tblHistory[BBB],tblHistory[Date],_xlfn.MAXIFS(tblHistory[Date],tblHistory[BBB],"<>")) | F17: =E17-D17 | G17: 140 | H17: 250 | I17: — | J17: =MAX(MIN(1,MAX(0,(E17-G17)/(H17-G17))),MIN(1,MAX(0,(F17-L17)/(M17-L17)))) | K17: =IF(J17=1,"TRIGGERED",IF(J17>=0.5,"WARNING",IF(J17>0,"WATCH","CALM"))) | L17: 30 | M17: 100
B18: CCC high-yield spread (bp) (CCC) | C18: 0.06 | D18: =_xlfn.MINIFS(tblHistory[CCC],tblHistory[Date],"<="&MAX(tblHistory[Date]),tblHistory[Date],">="&MAX(tblHistory[Date])-365) | E18: =SUMIFS(tblHistory[CCC],tblHistory[Date],_xlfn.MAXIFS(tblHistory[Date],tblHistory[CCC],"<>")) | F18: =E18-D18 | G18: 900 | H18: 1500 | I18: — | J18: =MAX(MIN(1,MAX(0,(E18-G18)/(H18-G18))),MIN(1,MAX(0,(F18-L18)/(M18-L18)))) | K18: =IF(J18=1,"TRIGGERED",IF(J18>=0.5,"WARNING",IF(J18>0,"WATCH","CALM"))) | L18: 150 | M18: 500
B19: BDC (private credit) ETF (BIZD) | C19: 0.14 | D19: =_xlfn.MAXIFS(tblHistory[BIZD],tblHistory[Date],"<="&MAX(tblHistory[Date]),tblHistory[Date],">="&MAX(tblHistory[Date])-730) | E19: =SUMIFS(tblHistory[BIZD],tblHistory[Date],_xlfn.MAXIFS(tblHistory[Date],tblHistory[BIZD],"<>")) | F19: =E19/D19-1 | G19: -0.05 | H19: -0.25 | I19: =D19*(1+H19) | J19: =MIN(1,MAX(0,(F19-G19)/(H19-G19))) | K19: =IF(J19=1,"TRIGGERED",IF(J19>=0.5,"WARNING",IF(J19>0,"WATCH","CALM")))
B20: Leveraged loan ETF (BKLN) | C20: 0.13 | D20: =_xlfn.MAXIFS(tblHistory[BKLN],tblHistory[Date],"<="&MAX(tblHistory[Date]),tblHistory[Date],">="&MAX(tblHistory[Date])-730) | E20: =SUMIFS(tblHistory[BKLN],tblHistory[Date],_xlfn.MAXIFS(tblHistory[Date],tblHistory[BKLN],"<>")) | F20: =E20/D20-1 | G20: -0.02 | H20: -0.08 | I20: =D20*(1+H20) | J20: =MIN(1,MAX(0,(F20-G20)/(H20-G20))) | K20: =IF(J20=1,"TRIGGERED",IF(J20>=0.5,"WARNING",IF(J20>0,"WATCH","CALM")))
B21: High-yield spread (bp) (HY) | C21: 0.1 | D21: =_xlfn.MINIFS(tblHistory[HY],tblHistory[Date],"<="&MAX(tblHistory[Date]),tblHistory[Date],">="&MAX(tblHistory[Date])-365) | E21: =SUMIFS(tblHistory[HY],tblHistory[Date],_xlfn.MAXIFS(tblHistory[Date],tblHistory[HY],"<>")) | F21: =E21-D21 | G21: 400 | H21: 600 | I21: =IF(E21<300,"Very Healthy",IF(E21<400,"Normal",IF(E21<500,"Watch",IF(E21<600,"Warning",IF(E21<800,"Severe Stress","Crisis"))))) | J21: =MAX(MIN(1,MAX(0,(E21-G21)/(H21-G21))),MIN(1,MAX(0,(F21-L21)/(M21-L21)))) | K21: =IF(J21=1,"TRIGGERED",IF(J21>=0.5,"WARNING",IF(J21>0,"WATCH","CALM"))) | L21: 75 | M21: 250
B22: Total weight | C22: =SUM(C13:C21)
B23: How it works: Prices: drawdown = dividend-adjusted close ÷ highest close of the last 2 years − 1; stress = clamp((x − Calm)/(Trigger − Calm), 0, 1). Spreads (bp): stress = the higher of the level test (Calm/Trigger) and the widening test (+bp over the 52-week low vs Widen calm/trigger). Score = weighted stress × 100. Levels need 5 straight trading days: L1 Score≥50 · L2 Score≥60 + (BIZD≥80% + BKLN≥50%, or CCC≥80%) · L3 Score≥70 + SOX≥83% + AIQ≥80% · L4 Score≥75 + NDX=100% + (HY≥500bp or BIZD=100%). Implosion date = first day of the first L4 streak. Levels are independent tripwires; they show PAUSED in recovery mode (Nasdaq-100 20%+ above its low since its 2-year high). Shock flag: Score≥60 with no level confirmed. Blue cells are editable.
B78: AI Implosion Dashboard · designed by KK Reddy

Sheet Tracker
B2: TRACKER — score & levels
B4: Latest date | C4: =MAX(tblHistory[Date])
B5: Score | C5: =INDEX(tblHistory[Score],MATCH(C4,tblHistory[Date],0))
B6: Triggers | C6: =COUNTIF(Dashboard!K13:K21,"TRIGGERED")&" of 9"
B7: Band | C7: =IF(C18<>"","IMPLOSION CONFIRMED",IFERROR(IF(C5<25,"NORMAL",IF(C5<50,"ELEVATED",IF(C5<75,"SEVERE","CRITICAL"))),"WARM-UP"))
B10: LEVELS
B11: Level | C11: Name | D11: First date (5-day start) | E11: Active now
B12: L1 | C12: Warning | D12: =IF(COUNTIF(tblHistory[L1S],1),_xlfn.MINIFS(tblHistory[Date],tblHistory[L1S],1),"") | E12: =IF(COUNTIFS(tblHistory[Date],">="&LARGE(tblHistory[Date],5),tblHistory[L1],1)=5,IF(C21="ON","PAUSED (recovery)","YES"),"NO")
B13: L2 | C13: Financing Stress | D13: =IF(COUNTIF(tblHistory[L2S],1),_xlfn.MINIFS(tblHistory[Date],tblHistory[L2S],1),"") | E13: =IF(COUNTIFS(tblHistory[Date],">="&LARGE(tblHistory[Date],5),tblHistory[L2],1)=5,IF(C21="ON","PAUSED (recovery)","YES"),"NO")
B14: L3 | C14: Bubble Unwind | D14: =IF(COUNTIF(tblHistory[L3S],1),_xlfn.MINIFS(tblHistory[Date],tblHistory[L3S],1),"") | E14: =IF(COUNTIFS(tblHistory[Date],">="&LARGE(tblHistory[Date],5),tblHistory[L3],1)=5,IF(C21="ON","PAUSED (recovery)","YES"),"NO")
B15: L4 | C15: AI Implosion | D15: =IF(COUNTIF(tblHistory[L4S],1),_xlfn.MINIFS(tblHistory[Date],tblHistory[L4S],1),"") | E15: =IF(COUNTIFS(tblHistory[Date],">="&LARGE(tblHistory[Date],5),tblHistory[L4],1)=5,IF(C21="ON","PAUSED (recovery)","YES"),"NO")
B17: Current level | C17: =IF(E15="YES","L4 AI Implosion",IF(E14="YES","L3 Bubble Unwind",IF(E13="YES","L2 Financing Stress",IF(E12="YES","L1 Warning","None"))))
B18: AI Implosion date | C18: =D15
B19: Shock flag | C19: =IF(AND(N(C5)>=60,COUNTIF(E12:E15,"NO")=4),"ON","off")
B21: Recovery mode | C21: =IF(IFERROR(ROUND(INDEX(tblHistory[NDX],MATCH(C4,tblHistory[Date],0))/_xlfn.MINIFS(tblHistory[NDX],tblHistory[Date],">="&_xlfn.MAXIFS(tblHistory[Date],tblHistory[NDX],_xlfn.MAXIFS(tblHistory[NDX],tblHistory[Date],">="&C4-730,tblHistory[Date],"<="&C4),tblHistory[Date],">="&C4-730,tblHistory[Date],"<="&C4),tblHistory[Date],"<="&C4)-1,9),0)>=0.2,"ON","off") | D21: =IFERROR(INDEX(tblHistory[NDX],MATCH(C4,tblHistory[Date],0))/_xlfn.MINIFS(tblHistory[NDX],tblHistory[Date],">="&_xlfn.MAXIFS(tblHistory[Date],tblHistory[NDX],_xlfn.MAXIFS(tblHistory[NDX],tblHistory[Date],">="&C4-730,tblHistory[Date],"<="&C4),tblHistory[Date],">="&C4-730,tblHistory[Date],"<="&C4),tblHistory[Date],"<="&C4)-1,"")
B23: Levels are independent tripwires, not a ladder. Recovery mode = Nasdaq-100 20%+ above its lowest close since its 2-year high; active levels show PAUSED then, and start dates never move. Shock flag = score ≥ 60 with no level confirmed (not a level).

Sheet History
A1: LIVE DATA — Yahoo Finance dividend-adjusted closes + FRED spreads (x100, bp). Auto-refreshed 27-Oct-2026 22:49. Newest row on top.
A2: Inputs: Date + 9 values (light blue). Everything from 'NDX S' onward is calculated — don't type there. Blank cells carry the last value.
A3: Date | B3: NDX | C3: SOX | D3: AIQ | E3: DTCR | F3: BBB | G3: CCC | H3: BIZD | I3: BKLN | J3: HY | K3: NDX S | L3: SOX S | M3: AIQ S | N3: DTCR S | O3: BBB S | P3: CCC S | Q3: BIZD S | R3: BKLN S | S3: HY S | T3: EquityP | U3: FinP | V3: CreditP | W3: Score | X3: L1 | Y3: L2 | Z3: L3 | AA3: L4 | AB3: L1S | AC3: L2S | AD3: L3S | AE3: L4S
A4: 46322 | B4: 29651.441 | C4: 11482.505 | D4: 63.66 | E4: 26.13 | H4: 12.09 | I4: 20.38 | K4: =IF(tblHistory[[#This Row],[Date]]-MIN(tblHistory[Date])<729,NA(),IF(IF(ISNUMBER(tblHistory[[#This Row],[NDX]]),tblHistory[[#This Row],[NDX]],SUMIFS(tblHistory[NDX],tblHistory[Date],_xlfn.MAXIFS(tblHistory[Date],tblHistory[Date],"<"&tblHistory[[#This Row],[Date]],tblHistory[NDX],"<>")))=0,0,MIN(1,MAX(0,((IF(ISNUMBER(tblHistory[[#This Row],[NDX]]),tblHistory[[#This Row],[NDX]],SUMIFS(tblHistory[NDX],tblHistory[Date],_xlfn.MAXIFS(tblHistory[Date],tblHistory[Date],"<"&tblHistory[[#This Row],[Date]],tblHistory[NDX],"<>")))/_xlfn.MAXIFS(tblHistory[NDX],tblHistory[Date],"<="&tblHistory[[#This Row],[Date]],tblHistory[Date],">="&tblHistory[[#This Row],[Date]]-730)-1)-Dashboard!$G$13)/(Dashboard!$H$13-Dashboard!$G$13))))) | L4: =IF(tblHistory[[#This Row],[Date]]-MIN(tblHistory[Date])<729,NA(),IF(IF(ISNUMBER(tblHistory[[#This Row],[SOX]]),tblHistory[[#This Row],[SOX]],SUMIFS(tblHistory[SOX],tblHistory[Date],_xlfn.MAXIFS(tblHistory[Date],tblHistory[Date],"<"&tblHistory[[#This Row],[Date]],tblHistory[SOX],"<>")))=0,0,MIN(1,MAX(0,((IF(ISNUMBER(tblHistory[[#This Row],[SOX]]),tblHistory[[#This Row],[SOX]],SUMIFS(tblHistory[SOX],tblHistory[Date],_xlfn.MAXIFS(tblHistory[Date],tblHistory[Date],"<"&tblHistory[[#This Row],[Date]],tblHistory[SOX],"<>")))/_xlfn.MAXIFS(tblHistory[SOX],tblHistory[Date],"<="&tblHistory[[#This Row],[Date]],tblHistory[Date],">="&tblHistory[[#This Row],[Date]]-730)-1)-Dashboard!$G$14)/(Dashboard!$H$14-Dashboard!$G$14))))) | M4: =IF(tblHistory[[#This Row],[Date]]-MIN(tblHistory[Date])<729,NA(),IF(IF(ISNUMBER(tblHistory[[#This Row],[AIQ]]),tblHistory[[#This Row],[AIQ]],SUMIFS(tblHistory[AIQ],tblHistory[Date],_xlfn.MAXIFS(tblHistory[Date],tblHistory[Date],"<"&tblHistory[[#This Row],[Date]],tblHistory[AIQ],"<>")))=0,0,MIN(1,MAX(0,((IF(ISNUMBER(tblHistory[[#This Row],[AIQ]]),tblHistory[[#This Row],[AIQ]],SUMIFS(tblHistory[AIQ],tblHistory[Date],_xlfn.MAXIFS(tblHistory[Date],tblHistory[Date],"<"&tblHistory[[#This Row],[Date]],tblHistory[AIQ],"<>")))/_xlfn.MAXIFS(tblHistory[AIQ],tblHistory[Date],"<="&tblHistory[[#This Row],[Date]],tblHistory[Date],">="&tblHistory[[#This Row],[Date]]-730)-1)-Dashboard!$G$15)/(Dashboard!$H$15-Dashboard!$G$15))))) | N4: =IF(tblHistory[[#This Row],[Date]]-MIN(tblHistory[Date])<729,NA(),IF(IF(ISNUMBER(tblHistory[[#This Row],[DTCR]]),tblHistory[[#This Row],[DTCR]],SUMIFS(tblHistory[DTCR],tblHistory[Date],_xlfn.MAXIFS(tblHistory[Date],tblHistory[Date],"<"&tblHistory[[#This Row],[Date]],tblHistory[DTCR],"<>")))=0,0,MIN(1,MAX(0,((IF(ISNUMBER(tblHistory[[#This Row],[DTCR]]),tblHistory[[#This Row],[DTCR]],SUMIFS(tblHistory[DTCR],tblHistory[Date],_xlfn.MAXIFS(tblHistory[Date],tblHistory[Date],"<"&tblHistory[[#This Row],[Date]],tblHistory[DTCR],"<>")))/_xlfn.MAXIFS(tblHistory[DTCR],tblHistory[Date],"<="&tblHistory[[#This Row],[Date]],tblHistory[Date],">="&tblHistory[[#This Row],[Date]]-730)-1)-Dashboard!$G$16)/(Dashboard!$H$16-Dashboard!$G$16))))) | O4: =IF(tblHistory[[#This Row],[Date]]-MIN(tblHistory[Date])<729,NA(),MAX(MIN(1,MAX(0,(IF(ISNUMBER(tblHistory[[#This Row],[BBB]]),tblHistory[[#This Row],[BBB]],SUMIFS(tblHistory[BBB],tblHistory[Date],_xlfn.MAXIFS(tblHistory[Date],tblHistory[Date],"<"&tblHistory[[#This Row],[Date]],tblHistory[BBB],"<>")))-Dashboard!$G$17)/(Dashboard!$H$17-Dashboard!$G$17))),MIN(1,MAX(0,(IF(ISNUMBER(tblHistory[[#This Row],[BBB]]),tblHistory[[#This Row],[BBB]],SUMIFS(tblHistory[BBB],tblHistory[Date],_xlfn.MAXIFS(tblHistory[Date],tblHistory[Date],"<"&tblHistory[[#This Row],[Date]],tblHistory[BBB],"<>")))-_xlfn.MINIFS(tblHistory[BBB],tblHistory[Date],"<="&tblHistory[[#This Row],[Date]],tblHistory[Date],">="&tblHistory[[#This Row],[Date]]-365)-Dashboard!$L$17)/(Dashboard!$M$17-Dashboard!$L$17))))) | P4: =IF(tblHistory[[#This Row],[Date]]-MIN(tblHistory[Date])<729,NA(),MAX(MIN(1,MAX(0,(IF(ISNUMBER(tblHistory[[#This Row],[CCC]]),tblHistory[[#This Row],[CCC]],SUMIFS(tblHistory[CCC],tblHistory[Date],_xlfn.MAXIFS(tblHistory[Date],tblHistory[Date],"<"&tblHistory[[#This Row],[Date]],tblHistory[CCC],"<>")))-Dashboard!$G$18)/(Dashboard!$H$18-Dashboard!$G$18))),MIN(1,MAX(0,(IF(ISNUMBER(tblHistory[[#This Row],[CCC]]),tblHistory[[#This Row],[CCC]],SUMIFS(tblHistory[CCC],tblHistory[Date],_xlfn.MAXIFS(tblHistory[Date],tblHistory[Date],"<"&tblHistory[[#This Row],[Date]],tblHistory[CCC],"<>")))-_xlfn.MINIFS(tblHistory[CCC],tblHistory[Date],"<="&tblHistory[[#This Row],[Date]],tblHistory[Date],">="&tblHistory[[#This Row],[Date]]-365)-Dashboard!$L$18)/(Dashboard!$M$18-Dashboard!$L$18))))) | Q4: =IF(tblHistory[[#This Row],[Date]]-MIN(tblHistory[Date])<729,NA(),IF(IF(ISNUMBER(tblHistory[[#This Row],[BIZD]]),tblHistory[[#This Row],[BIZD]],SUMIFS(tblHistory[BIZD],tblHistory[Date],_xlfn.MAXIFS(tblHistory[Date],tblHistory[Date],"<"&tblHistory[[#This Row],[Date]],tblHistory[BIZD],"<>")))=0,0,MIN(1,MAX(0,((IF(ISNUMBER(tblHistory[[#This Row],[BIZD]]),tblHistory[[#This Row],[BIZD]],SUMIFS(tblHistory[BIZD],tblHistory[Date],_xlfn.MAXIFS(tblHistory[Date],tblHistory[Date],"<"&tblHistory[[#This Row],[Date]],tblHistory[BIZD],"<>")))/_xlfn.MAXIFS(tblHistory[BIZD],tblHistory[Date],"<="&tblHistory[[#This Row],[Date]],tblHistory[Date],">="&tblHistory[[#This Row],[Date]]-730)-1)-Dashboard!$G$19)/(Dashboard!$H$19-Dashboard!$G$19))))) | R4: =IF(tblHistory[[#This Row],[Date]]-MIN(tblHistory[Date])<729,NA(),IF(IF(ISNUMBER(tblHistory[[#This Row],[BKLN]]),tblHistory[[#This Row],[BKLN]],SUMIFS(tblHistory[BKLN],tblHistory[Date],_xlfn.MAXIFS(tblHistory[Date],tblHistory[Date],"<"&tblHistory[[#This Row],[Date]],tblHistory[BKLN],"<>")))=0,0,MIN(1,MAX(0,((IF(ISNUMBER(tblHistory[[#This Row],[BKLN]]),tblHistory[[#This Row],[BKLN]],SUMIFS(tblHistory[BKLN],tblHistory[Date],_xlfn.MAXIFS(tblHistory[Date],tblHistory[Date],"<"&tblHistory[[#This Row],[Date]],tblHistory[BKLN],"<>")))/_xlfn.MAXIFS(tblHistory[BKLN],tblHistory[Date],"<="&tblHistory[[#This Row],[Date]],tblHistory[Date],">="&tblHistory[[#This Row],[Date]]-730)-1)-Dashboard!$G$20)/(Dashboard!$H$20-Dashboard!$G$20))))) | S4: =IF(tblHistory[[#This Row],[Date]]-MIN(tblHistory[Date])<729,NA(),MAX(MIN(1,MAX(0,(IF(ISNUMBER(tblHistory[[#This Row],[HY]]),tblHistory[[#This Row],[HY]],SUMIFS(tblHistory[HY],tblHistory[Date],_xlfn.MAXIFS(tblHistory[Date],tblHistory[Date],"<"&tblHistory[[#This Row],[Date]],tblHistory[HY],"<>")))-Dashboard!$G$21)/(Dashboard!$H$21-Dashboard!$G$21))),MIN(1,MAX(0,(IF(ISNUMBER(tblHistory[[#This Row],[HY]]),tblHistory[[#This Row],[HY]],SUMIFS(tblHistory[HY],tblHistory[Date],_xlfn.MAXIFS(tblHistory[Date],tblHistory[Date],"<"&tblHistory[[#This Row],[Date]],tblHistory[HY],"<>")))-_xlfn.MINIFS(tblHistory[HY],tblHistory[Date],"<="&tblHistory[[#This Row],[Date]],tblHistory[Date],">="&tblHistory[[#This Row],[Date]]-365)-Dashboard!$L$21)/(Dashboard!$M$21-Dashboard!$L$21))))) | T4: =(Dashboard!$C$13*tblHistory[[#This Row],[NDX S]]+Dashboard!$C$14*tblHistory[[#This Row],[SOX S]]+Dashboard!$C$15*tblHistory[[#This Row],[AIQ S]])/(Dashboard!$C$13+Dashboard!$C$14+Dashboard!$C$15)*100 | U4: =(Dashboard!$C$16*tblHistory[[#This Row],[DTCR S]]+Dashboard!$C$17*tblHistory[[#This Row],[BBB S]]+Dashboard!$C$18*tblHistory[[#This Row],[CCC S]])/(Dashboard!$C$16+Dashboard!$C$17+Dashboard!$C$18)*100 | V4: =(Dashboard!$C$19*tblHistory[[#This Row],[BIZD S]]+Dashboard!$C$20*tblHistory[[#This Row],[BKLN S]]+Dashboard!$C$21*tblHistory[[#This Row],[HY S]])/(Dashboard!$C$19+Dashboard!$C$20+Dashboard!$C$21)*100 | W4: =ROUND((Dashboard!$C$13*tblHistory[[#This Row],[NDX S]]+Dashboard!$C$14*tblHistory[[#This Row],[SOX S]]+Dashboard!$C$15*tblHistory[[#This Row],[AIQ S]]+Dashboard!$C$16*tblHistory[[#This Row],[DTCR S]]+Dashboard!$C$17*tblHistory[[#This Row],[BBB S]]+Dashboard!$C$18*tblHistory[[#This Row],[CCC S]]+Dashboard!$C$19*tblHistory[[#This Row],[BIZD S]]+Dashboard!$C$20*tblHistory[[#This Row],[BKLN S]]+Dashboard!$C$21*tblHistory[[#This Row],[HY S]])/(Dashboard!$C$13+Dashboard!$C$14+Dashboard!$C$15+Dashboard!$C$16+Dashboard!$C$17+Dashboard!$C$18+Dashboard!$C$19+Dashboard!$C$20+Dashboard!$C$21)*100,0) | X4: =IFERROR(--(tblHistory[[#This Row],[Score]]>=50),0) | Y4: =IFERROR(--AND(tblHistory[[#This Row],[Score]]>=60,OR(AND(tblHistory[[#This Row],[BIZD S]]>=0.8,tblHistory[[#This Row],[BKLN S]]>=0.5),tblHistory[[#This Row],[CCC S]]>=0.8)),0) | Z4: =IFERROR(--AND(tblHistory[[#This Row],[Score]]>=70,tblHistory[[#This Row],[SOX S]]>=0.83,tblHistory[[#This Row],[AIQ S]]>=0.8),0) | AA4: =IFERROR(--AND(tblHistory[[#This Row],[Score]]>=75,tblHistory[[#This Row],[NDX S]]=1,OR(IF(ISNUMBER(tblHistory[[#This Row],[HY]]),tblHistory[[#This Row],[HY]],SUMIFS(tblHistory[HY],tblHistory[Date],_xlfn.MAXIFS(tblHistory[Date],tblHistory[Date],"<"&tblHistory[[#This Row],[Date]],tblHistory[HY],"<>")))>=500,tblHistory[[#This Row],[BIZD S]]=1)),0) | AB4: =IFERROR(--(COUNTIFS(tblHistory[Date],">="&tblHistory[[#This Row],[Date]],tblHistory[Date],"<="&_xlfn.AGGREGATE(15,6,tblHistory[Date]/(tblHistory[Date]>=tblHistory[[#This Row],[Date]]),5),tblHistory[L1],1)=5),0) | AC4: =IFERROR(--(COUNTIFS(tblHistory[Date],">="&tblHistory[[#This Row],[Date]],tblHistory[Date],"<="&_xlfn.AGGREGATE(15,6,tblHistory[Date]/(tblHistory[Date]>=tblHistory[[#This Row],[Date]]),5),tblHistory[L2],1)=5),0) | AD4: =IFERROR(--(COUNTIFS(tblHistory[Date],">="&tblHistory[[#This Row],[Date]],tblHistory[Date],"<="&_xlfn.AGGREGATE(15,6,tblHistory[Date]/(tblHistory[Date]>=tblHistory[[#This Row],[Date]]),5),tblHistory[L3],1)=5),0) | AE4: =IFERROR(--(COUNTIFS(tblHistory[Date],">="&tblHistory[[#This Row],[Date]],tblHistory[Date],"<="&_xlfn.AGGREGATE(15,6,tblHistory[Date]/(tblHistory[Date]>=tblHistory[[#This Row],[Date]]),5),tblHistory[L4],1)=5),0)
A5: 46321 | B5: 29273.4 | C5: 11083.47 | D5: 62.94 | E5: 25.68 | F5: 112 | G5: 1345 | H5: 11.9 | I5: 20.3 | J5: 330 | K5: =IF(tblHistory[[#This Row],[Date]]-MIN(tblHistory[Date])<729,NA(),IF(IF(ISNUMBER(tblHistory[[#This Row],[NDX]]),tblHistory[[#This Row],[NDX]],SUMIFS(tblHistory[NDX],tblHistory[Date],_xlfn.MAXIFS(tblHistory[Date],tblHistory[Date],"<"&tblHistory[[#This Row],[Date]],tblHistory[NDX],"<>")))=0,0,MIN(1,MAX(0,((IF(ISNUMBER(tblHistory[[#This Row],[NDX]]),tblHistory[[#This Row],[NDX]],SUMIFS(tblHistory[NDX],tblHistory[Date],_xlfn.MAXIFS(tblHistory[Date],tblHistory[Date],"<"&tblHistory[[#This Row],[Date]],tblHistory[NDX],"<>")))/_xlfn.MAXIFS(tblHistory[NDX],tblHistory[Date],"<="&tblHistory[[#This Row],[Date]],tblHistory[Date],">="&tblHistory[[#This Row],[Date]]-730)-1)-Dashboard!$G$13)/(Dashboard!$H$13-Dashboard!$G$13))))) | L5: =IF(tblHistory[[#This Row],[Date]]-MIN(tblHistory[Date])<729,NA(),IF(IF(ISNUMBER(tblHistory[[#This Row],[SOX]]),tblHistory[[#This Row],[SOX]],SUMIFS(tblHistory[SOX],tblHistory[Date],_xlfn.MAXIFS(tblHistory[Date],tblHistory[Date],"<"&tblHistory[[#This Row],[Date]],tblHistory[SOX],"<>")))=0,0,MIN(1,MAX(0,((IF(ISNUMBER(tblHistory[[#This Row],[SOX]]),tblHistory[[#This Row],[SOX]],SUMIFS(tblHistory[SOX],tblHistory[Date],_xlfn.MAXIFS(tblHistory[Date],tblHistory[Date],"<"&tblHistory[[#This Row],[Date]],tblHistory[SOX],"<>")))/_xlfn.MAXIFS(tblHistory[SOX],tblHistory[Date],"<="&tblHistory[[#This Row],[Date]],tblHistory[Date],">="&tblHistory[[#This Row],[Date]]-730)-1)-Dashboard!$G$14)/(Dashboard!$H$14-Dashboard!$G$14))))) | M5: =IF(tblHistory[[#This Row],[Date]]-MIN(tblHistory[Date])<729,NA(),IF(IF(ISNUMBER(tblHistory[[#This Row],[AIQ]]),tblHistory[[#This Row],[AIQ]],SUMIFS(tblHistory[AIQ],tblHistory[Date],_xlfn.MAXIFS(tblHistory[Date],tblHistory[Date],"<"&tblHistory[[#This Row],[Date]],tblHistory[AIQ],"<>")))=0,0,MIN(1,MAX(0,((IF(ISNUMBER(tblHistory[[#This Row],[AIQ]]),tblHistory[[#This Row],[AIQ]],SUMIFS(tblHistory[AIQ],tblHistory[Date],_xlfn.MAXIFS(tblHistory[Date],tblHistory[Date],"<"&tblHistory[[#This Row],[Date]],tblHistory[AIQ],"<>")))/_xlfn.MAXIFS(tblHistory[AIQ],tblHistory[Date],"<="&tblHistory[[#This Row],[Date]],tblHistory[Date],">="&tblHistory[[#This Row],[Date]]-730)-1)-Dashboard!$G$15)/(Dashboard!$H$15-Dashboard!$G$15))))) | N5: =IF(tblHistory[[#This Row],[Date]]-MIN(tblHistory[Date])<729,NA(),IF(IF(ISNUMBER(tblHistory[[#This Row],[DTCR]]),tblHistory[[#This Row],[DTCR]],SUMIFS(tblHistory[DTCR],tblHistory[Date],_xlfn.MAXIFS(tblHistory[Date],tblHistory[Date],"<"&tblHistory[[#This Row],[Date]],tblHistory[DTCR],"<>")))=0,0,MIN(1,MAX(0,((IF(ISNUMBER(tblHistory[[#This Row],[DTCR]]),tblHistory[[#This Row],[DTCR]],SUMIFS(tblHistory[DTCR],tblHistory[Date],_xlfn.MAXIFS(tblHistory[Date],tblHistory[Date],"<"&tblHistory[[#This Row],[Date]],tblHistory[DTCR],"<>")))/_xlfn.MAXIFS(tblHistory[DTCR],tblHistory[Date],"<="&tblHistory[[#This Row],[Date]],tblHistory[Date],">="&tblHistory[[#This Row],[Date]]-730)-1)-Dashboard!$G$16)/(Dashboard!$H$16-Dashboard!$G$16))))) | O5: =IF(tblHistory[[#This Row],[Date]]-MIN(tblHistory[Date])<729,NA(),MAX(MIN(1,MAX(0,(IF(ISNUMBER(tblHistory[[#This Row],[BBB]]),tblHistory[[#This Row],[BBB]],SUMIFS(tblHistory[BBB],tblHistory[Date],_xlfn.MAXIFS(tblHistory[Date],tblHistory[Date],"<"&tblHistory[[#This Row],[Date]],tblHistory[BBB],"<>")))-Dashboard!$G$17)/(Dashboard!$H$17-Dashboard!$G$17))),MIN(1,MAX(0,(IF(ISNUMBER(tblHistory[[#This Row],[BBB]]),tblHistory[[#This Row],[BBB]],SUMIFS(tblHistory[BBB],tblHistory[Date],_xlfn.MAXIFS(tblHistory[Date],tblHistory[Date],"<"&tblHistory[[#This Row],[Date]],tblHistory[BBB],"<>")))-_xlfn.MINIFS(tblHistory[BBB],tblHistory[Date],"<="&tblHistory[[#This Row],[Date]],tblHistory[Date],">="&tblHistory[[#This Row],[Date]]-365)-Dashboard!$L$17)/(Dashboard!$M$17-Dashboard!$L$17))))) | P5: =IF(tblHistory[[#This Row],[Date]]-MIN(tblHistory[Date])<729,NA(),MAX(MIN(1,MAX(0,(IF(ISNUMBER(tblHistory[[#This Row],[CCC]]),tblHistory[[#This Row],[CCC]],SUMIFS(tblHistory[CCC],tblHistory[Date],_xlfn.MAXIFS(tblHistory[Date],tblHistory[Date],"<"&tblHistory[[#This Row],[Date]],tblHistory[CCC],"<>")))-Dashboard!$G$18)/(Dashboard!$H$18-Dashboard!$G$18))),MIN(1,MAX(0,(IF(ISNUMBER(tblHistory[[#This Row],[CCC]]),tblHistory[[#This Row],[CCC]],SUMIFS(tblHistory[CCC],tblHistory[Date],_xlfn.MAXIFS(tblHistory[Date],tblHistory[Date],"<"&tblHistory[[#This Row],[Date]],tblHistory[CCC],"<>")))-_xlfn.MINIFS(tblHistory[CCC],tblHistory[Date],"<="&tblHistory[[#This Row],[Date]],tblHistory[Date],">="&tblHistory[[#This Row],[Date]]-365)-Dashboard!$L$18)/(Dashboard!$M$18-Dashboard!$L$18))))) | Q5: =IF(tblHistory[[#This Row],[Date]]-MIN(tblHistory[Date])<729,NA(),IF(IF(ISNUMBER(tblHistory[[#This Row],[BIZD]]),tblHistory[[#This Row],[BIZD]],SUMIFS(tblHistory[BIZD],tblHistory[Date],_xlfn.MAXIFS(tblHistory[Date],tblHistory[Date],"<"&tblHistory[[#This Row],[Date]],tblHistory[BIZD],"<>")))=0,0,MIN(1,MAX(0,((IF(ISNUMBER(tblHistory[[#This Row],[BIZD]]),tblHistory[[#This Row],[BIZD]],SUMIFS(tblHistory[BIZD],tblHistory[Date],_xlfn.MAXIFS(tblHistory[Date],tblHistory[Date],"<"&tblHistory[[#This Row],[Date]],tblHistory[BIZD],"<>")))/_xlfn.MAXIFS(tblHistory[BIZD],tblHistory[Date],"<="&tblHistory[[#This Row],[Date]],tblHistory[Date],">="&tblHistory[[#This Row],[Date]]-730)-1)-Dashboard!$G$19)/(Dashboard!$H$19-Dashboard!$G$19))))) | R5: =IF(tblHistory[[#This Row],[Date]]-MIN(tblHistory[Date])<729,NA(),IF(IF(ISNUMBER(tblHistory[[#This Row],[BKLN]]),tblHistory[[#This Row],[BKLN]],SUMIFS(tblHistory[BKLN],tblHistory[Date],_xlfn.MAXIFS(tblHistory[Date],tblHistory[Date],"<"&tblHistory[[#This Row],[Date]],tblHistory[BKLN],"<>")))=0,0,MIN(1,MAX(0,((IF(ISNUMBER(tblHistory[[#This Row],[BKLN]]),tblHistory[[#This Row],[BKLN]],SUMIFS(tblHistory[BKLN],tblHistory[Date],_xlfn.MAXIFS(tblHistory[Date],tblHistory[Date],"<"&tblHistory[[#This Row],[Date]],tblHistory[BKLN],"<>")))/_xlfn.MAXIFS(tblHistory[BKLN],tblHistory[Date],"<="&tblHistory[[#This Row],[Date]],tblHistory[Date],">="&tblHistory[[#This Row],[Date]]-730)-1)-Dashboard!$G$20)/(Dashboard!$H$20-Dashboard!$G$20))))) | S5: =IF(tblHistory[[#This Row],[Date]]-MIN(tblHistory[Date])<729,NA(),MAX(MIN(1,MAX(0,(IF(ISNUMBER(tblHistory[[#This Row],[HY]]),tblHistory[[#This Row],[HY]],SUMIFS(tblHistory[HY],tblHistory[Date],_xlfn.MAXIFS(tblHistory[Date],tblHistory[Date],"<"&tblHistory[[#This Row],[Date]],tblHistory[HY],"<>")))-Dashboard!$G$21)/(Dashboard!$H$21-Dashboard!$G$21))),MIN(1,MAX(0,(IF(ISNUMBER(tblHistory[[#This Row],[HY]]),tblHistory[[#This Row],[HY]],SUMIFS(tblHistory[HY],tblHistory[Date],_xlfn.MAXIFS(tblHistory[Date],tblHistory[Date],"<"&tblHistory[[#This Row],[Date]],tblHistory[HY],"<>")))-_xlfn.MINIFS(tblHistory[HY],tblHistory[Date],"<="&tblHistory[[#This Row],[Date]],tblHistory[Date],">="&tblHistory[[#This Row],[Date]]-365)-Dashboard!$L$21)/(Dashboard!$M$21-Dashboard!$L$21))))) | T5: =(Dashboard!$C$13*tblHistory[[#This Row],[NDX S]]+Dashboard!$C$14*tblHistory[[#This Row],[SOX S]]+Dashboard!$C$15*tblHistory[[#This Row],[AIQ S]])/(Dashboard!$C$13+Dashboard!$C$14+Dashboard!$C$15)*100 | U5: =(Dashboard!$C$16*tblHistory[[#This Row],[DTCR S]]+Dashboard!$C$17*tblHistory[[#This Row],[BBB S]]+Dashboard!$C$18*tblHistory[[#This Row],[CCC S]])/(Dashboard!$C$16+Dashboard!$C$17+Dashboard!$C$18)*100 | V5: =(Dashboard!$C$19*tblHistory[[#This Row],[BIZD S]]+Dashboard!$C$20*tblHistory[[#This Row],[BKLN S]]+Dashboard!$C$21*tblHistory[[#This Row],[HY S]])/(Dashboard!$C$19+Dashboard!$C$20+Dashboard!$C$21)*100 | W5: =ROUND((Dashboard!$C$13*tblHistory[[#This Row],[NDX S]]+Dashboard!$C$14*tblHistory[[#This Row],[SOX S]]+Dashboard!$C$15*tblHistory[[#This Row],[AIQ S]]+Dashboard!$C$16*tblHistory[[#This Row],[DTCR S]]+Dashboard!$C$17*tblHistory[[#This Row],[BBB S]]+Dashboard!$C$18*tblHistory[[#This Row],[CCC S]]+Dashboard!$C$19*tblHistory[[#This Row],[BIZD S]]+Dashboard!$C$20*tblHistory[[#This Row],[BKLN S]]+Dashboard!$C$21*tblHistory[[#This Row],[HY S]])/(Dashboard!$C$13+Dashboard!$C$14+Dashboard!$C$15+Dashboard!$C$16+Dashboard!$C$17+Dashboard!$C$18+Dashboard!$C$19+Dashboard!$C$20+Dashboard!$C$21)*100,0) | X5: =IFERROR(--(tblHistory[[#This Row],[Score]]>=50),0) | Y5: =IFERROR(--AND(tblHistory[[#This Row],[Score]]>=60,OR(AND(tblHistory[[#This Row],[BIZD S]]>=0.8,tblHistory[[#This Row],[BKLN S]]>=0.5),tblHistory[[#This Row],[CCC S]]>=0.8)),0) | Z5: =IFERROR(--AND(tblHistory[[#This Row],[Score]]>=70,tblHistory[[#This Row],[SOX S]]>=0.83,tblHistory[[#This Row],[AIQ S]]>=0.8),0) | AA5: =IFERROR(--AND(tblHistory[[#This Row],[Score]]>=75,tblHistory[[#This Row],[NDX S]]=1,OR(IF(ISNUMBER(tblHistory[[#This Row],[HY]]),tblHistory[[#This Row],[HY]],SUMIFS(tblHistory[HY],tblHistory[Date],_xlfn.MAXIFS(tblHistory[Date],tblHistory[Date],"<"&tblHistory[[#This Row],[Date]],tblHistory[HY],"<>")))>=500,tblHistory[[#This Row],[BIZD S]]=1)),0) | AB5: =IFERROR(--(COUNTIFS(tblHistory[Date],">="&tblHistory[[#This Row],[Date]],tblHistory[Date],"<="&_xlfn.AGGREGATE(15,6,tblHistory[Date]/(tblHistory[Date]>=tblHistory[[#This Row],[Date]]),5),tblHistory[L1],1)=5),0) | AC5: =IFERROR(--(COUNTIFS(tblHistory[Date],">="&tblHistory[[#This Row],[Date]],tblHistory[Date],"<="&_xlfn.AGGREGATE(15,6,tblHistory[Date]/(tblHistory[Date]>=tblHistory[[#This Row],[Date]]),5),tblHistory[L2],1)=5),0) | AD5: =IFERROR(--(COUNTIFS(tblHistory[Date],">="&tblHistory[[#This Row],[Date]],tblHistory[Date],"<="&_xlfn.AGGREGATE(15,6,tblHistory[Date]/(tblHistory[Date]>=tblHistory[[#This Row],[Date]]),5),tblHistory[L3],1)=5),0) | AE5: =IFERROR(--(COUNTIFS(tblHistory[Date],">="&tblHistory[[#This Row],[Date]],tblHistory[Date],"<="&_xlfn.AGGREGATE(15,6,tblHistory[Date]/(tblHistory[Date]>=tblHistory[[#This Row],[Date]]),5),tblHistory[L4],1)=5),0)
A6: 46318 | B6: 28957.529 | C6: 10779.46 | D6: 62.29 | E6: 25.43 | F6: 113 | G6: 1356 | H6: 11.93 | I6: 20.26 | J6: 338 | K6: =IF(tblHistory[[#This Row],[Date]]-MIN(tblHistory[Date])<729,NA(),IF(IF(ISNUMBER(tblHistory[[#This Row],[NDX]]),tblHistory[[#This Row],[NDX]],SUMIFS(tblHistory[NDX],tblHistory[Date],_xlfn.MAXIFS(tblHistory[Date],tblHistory[Date],"<"&tblHistory[[#This Row],[Date]],tblHistory[NDX],"<>")))=0,0,MIN(1,MAX(0,((IF(ISNUMBER(tblHistory[[#This Row],[NDX]]),tblHistory[[#This Row],[NDX]],SUMIFS(tblHistory[NDX],tblHistory[Date],_xlfn.MAXIFS(tblHistory[Date],tblHistory[Date],"<"&tblHistory[[#This Row],[Date]],tblHistory[NDX],"<>")))/_xlfn.MAXIFS(tblHistory[NDX],tblHistory[Date],"<="&tblHistory[[#This Row],[Date]],tblHistory[Date],">="&tblHistory[[#This Row],[Date]]-730)-1)-Dashboard!$G$13)/(Dashboard!$H$13-Dashboard!$G$13))))) | L6: =IF(tblHistory[[#This Row],[Date]]-MIN(tblHistory[Date])<729,NA(),IF(IF(ISNUMBER(tblHistory[[#This Row],[SOX]]),tblHistory[[#This Row],[SOX]],SUMIFS(tblHistory[SOX],tblHistory[Date],_xlfn.MAXIFS(tblHistory[Date],tblHistory[Date],"<"&tblHistory[[#This Row],[Date]],tblHistory[SOX],"<>")))=0,0,MIN(1,MAX(0,((IF(ISNUMBER(tblHistory[[#This Row],[SOX]]),tblHistory[[#This Row],[SOX]],SUMIFS(tblHistory[SOX],tblHistory[Date],_xlfn.MAXIFS(tblHistory[Date],tblHistory[Date],"<"&tblHistory[[#This Row],[Date]],tblHistory[SOX],"<>")))/_xlfn.MAXIFS(tblHistory[SOX],tblHistory[Date],"<="&tblHistory[[#This Row],[Date]],tblHistory[Date],">="&tblHistory[[#This Row],[Date]]-730)-1)-Dashboard!$G$14)/(Dashboard!$H$14-Dashboard!$G$14))))) | M6: =IF(tblHistory[[#This Row],[Date]]-MIN(tblHistory[Date])<729,NA(),IF(IF(ISNUMBER(tblHistory[[#This Row],[AIQ]]),tblHistory[[#This Row],[AIQ]],SUMIFS(tblHistory[AIQ],tblHistory[Date],_xlfn.MAXIFS(tblHistory[Date],tblHistory[Date],"<"&tblHistory[[#This Row],[Date]],tblHistory[AIQ],"<>")))=0,0,MIN(1,MAX(0,((IF(ISNUMBER(tblHistory[[#This Row],[AIQ]]),tblHistory[[#This Row],[AIQ]],SUMIFS(tblHistory[AIQ],tblHistory[Date],_xlfn.MAXIFS(tblHistory[Date],tblHistory[Date],"<"&tblHistory[[#This Row],[Date]],tblHistory[AIQ],"<>")))/_xlfn.MAXIFS(tblHistory[AIQ],tblHistory[Date],"<="&tblHistory[[#This Row],[Date]],tblHistory[Date],">="&tblHistory[[#This Row],[Date]]-730)-1)-Dashboard!$G$15)/(Dashboard!$H$15-Dashboard!$G$15))))) | N6: =IF(tblHistory[[#This Row],[Date]]-MIN(tblHistory[Date])<729,NA(),IF(IF(ISNUMBER(tblHistory[[#This Row],[DTCR]]),tblHistory[[#This Row],[DTCR]],SUMIFS(tblHistory[DTCR],tblHistory[Date],_xlfn.MAXIFS(tblHistory[Date],tblHistory[Date],"<"&tblHistory[[#This Row],[Date]],tblHistory[DTCR],"<>")))=0,0,MIN(1,MAX(0,((IF(ISNUMBER(tblHistory[[#This Row],[DTCR]]),tblHistory[[#This Row],[DTCR]],SUMIFS(tblHistory[DTCR],tblHistory[Date],_xlfn.MAXIFS(tblHistory[Date],tblHistory[Date],"<"&tblHistory[[#This Row],[Date]],tblHistory[DTCR],"<>")))/_xlfn.MAXIFS(tblHistory[DTCR],tblHistory[Date],"<="&tblHistory[[#This Row],[Date]],tblHistory[Date],">="&tblHistory[[#This Row],[Date]]-730)-1)-Dashboard!$G$16)/(Dashboard!$H$16-Dashboard!$G$16))))) | O6: =IF(tblHistory[[#This Row],[Date]]-MIN(tblHistory[Date])<729,NA(),MAX(MIN(1,MAX(0,(IF(ISNUMBER(tblHistory[[#This Row],[BBB]]),tblHistory[[#This Row],[BBB]],SUMIFS(tblHistory[BBB],tblHistory[Date],_xlfn.MAXIFS(tblHistory[Date],tblHistory[Date],"<"&tblHistory[[#This Row],[Date]],tblHistory[BBB],"<>")))-Dashboard!$G$17)/(Dashboard!$H$17-Dashboard!$G$17))),MIN(1,MAX(0,(IF(ISNUMBER(tblHistory[[#This Row],[BBB]]),tblHistory[[#This Row],[BBB]],SUMIFS(tblHistory[BBB],tblHistory[Date],_xlfn.MAXIFS(tblHistory[Date],tblHistory[Date],"<"&tblHistory[[#This Row],[Date]],tblHistory[BBB],"<>")))-_xlfn.MINIFS(tblHistory[BBB],tblHistory[Date],"<="&tblHistory[[#This Row],[Date]],tblHistory[Date],">="&tblHistory[[#This Row],[Date]]-365)-Dashboard!$L$17)/(Dashboard!$M$17-Dashboard!$L$17))))) | P6: =IF(tblHistory[[#This Row],[Date]]-MIN(tblHistory[Date])<729,NA(),MAX(MIN(1,MAX(0,(IF(ISNUMBER(tblHistory[[#This Row],[CCC]]),tblHistory[[#This Row],[CCC]],SUMIFS(tblHistory[CCC],tblHistory[Date],_xlfn.MAXIFS(tblHistory[Date],tblHistory[Date],"<"&tblHistory[[#This Row],[Date]],tblHistory[CCC],"<>")))-Dashboard!$G$18)/(Dashboard!$H$18-Dashboard!$G$18))),MIN(1,MAX(0,(IF(ISNUMBER(tblHistory[[#This Row],[CCC]]),tblHistory[[#This Row],[CCC]],SUMIFS(tblHistory[CCC],tblHistory[Date],_xlfn.MAXIFS(tblHistory[Date],tblHistory[Date],"<"&tblHistory[[#This Row],[Date]],tblHistory[CCC],"<>")))-_xlfn.MINIFS(tblHistory[CCC],tblHistory[Date],"<="&tblHistory[[#This Row],[Date]],tblHistory[Date],">="&tblHistory[[#This Row],[Date]]-365)-Dashboard!$L$18)/(Dashboard!$M$18-Dashboard!$L$18))))) | Q6: =IF(tblHistory[[#This Row],[Date]]-MIN(tblHistory[Date])<729,NA(),IF(IF(ISNUMBER(tblHistory[[#This Row],[BIZD]]),tblHistory[[#This Row],[BIZD]],SUMIFS(tblHistory[BIZD],tblHistory[Date],_xlfn.MAXIFS(tblHistory[Date],tblHistory[Date],"<"&tblHistory[[#This Row],[Date]],tblHistory[BIZD],"<>")))=0,0,MIN(1,MAX(0,((IF(ISNUMBER(tblHistory[[#This Row],[BIZD]]),tblHistory[[#This Row],[BIZD]],SUMIFS(tblHistory[BIZD],tblHistory[Date],_xlfn.MAXIFS(tblHistory[Date],tblHistory[Date],"<"&tblHistory[[#This Row],[Date]],tblHistory[BIZD],"<>")))/_xlfn.MAXIFS(tblHistory[BIZD],tblHistory[Date],"<="&tblHistory[[#This Row],[Date]],tblHistory[Date],">="&tblHistory[[#This Row],[Date]]-730)-1)-Dashboard!$G$19)/(Dashboard!$H$19-Dashboard!$G$19))))) | R6: =IF(tblHistory[[#This Row],[Date]]-MIN(tblHistory[Date])<729,NA(),IF(IF(ISNUMBER(tblHistory[[#This Row],[BKLN]]),tblHistory[[#This Row],[BKLN]],SUMIFS(tblHistory[BKLN],tblHistory[Date],_xlfn.MAXIFS(tblHistory[Date],tblHistory[Date],"<"&tblHistory[[#This Row],[Date]],tblHistory[BKLN],"<>")))=0,0,MIN(1,MAX(0,((IF(ISNUMBER(tblHistory[[#This Row],[BKLN]]),tblHistory[[#This Row],[BKLN]],SUMIFS(tblHistory[BKLN],tblHistory[Date],_xlfn.MAXIFS(tblHistory[Date],tblHistory[Date],"<"&tblHistory[[#This Row],[Date]],tblHistory[BKLN],"<>")))/_xlfn.MAXIFS(tblHistory[BKLN],tblHistory[Date],"<="&tblHistory[[#This Row],[Date]],tblHistory[Date],">="&tblHistory[[#This Row],[Date]]-730)-1)-Dashboard!$G$20)/(Dashboard!$H$20-Dashboard!$G$20))))) | S6: =IF(tblHistory[[#This Row],[Date]]-MIN(tblHistory[Date])<729,NA(),MAX(MIN(1,MAX(0,(IF(ISNUMBER(tblHistory[[#This Row],[HY]]),tblHistory[[#This Row],[HY]],SUMIFS(tblHistory[HY],tblHistory[Date],_xlfn.MAXIFS(tblHistory[Date],tblHistory[Date],"<"&tblHistory[[#This Row],[Date]],tblHistory[HY],"<>")))-Dashboard!$G$21)/(Dashboard!$H$21-Dashboard!$G$21))),MIN(1,MAX(0,(IF(ISNUMBER(tblHistory[[#This Row],[HY]]),tblHistory[[#This Row],[HY]],SUMIFS(tblHistory[HY],tblHistory[Date],_xlfn.MAXIFS(tblHistory[Date],tblHistory[Date],"<"&tblHistory[[#This Row],[Date]],tblHistory[HY],"<>")))-_xlfn.MINIFS(tblHistory[HY],tblHistory[Date],"<="&tblHistory[[#This Row],[Date]],tblHistory[Date],">="&tblHistory[[#This Row],[Date]]-365)-Dashboard!$L$21)/(Dashboard!$M$21-Dashboard!$L$21))))) | T6: =(Dashboard!$C$13*tblHistory[[#This Row],[NDX S]]+Dashboard!$C$14*tblHistory[[#This Row],[SOX S]]+Dashboard!$C$15*tblHistory[[#This Row],[AIQ S]])/(Dashboard!$C$13+Dashboard!$C$14+Dashboard!$C$15)*100 | U6: =(Dashboard!$C$16*tblHistory[[#This Row],[DTCR S]]+Dashboard!$C$17*tblHistory[[#This Row],[BBB S]]+Dashboard!$C$18*tblHistory[[#This Row],[CCC S]])/(Dashboard!$C$16+Dashboard!$C$17+Dashboard!$C$18)*100 | V6: =(Dashboard!$C$19*tblHistory[[#This Row],[BIZD S]]+Dashboard!$C$20*tblHistory[[#This Row],[BKLN S]]+Dashboard!$C$21*tblHistory[[#This Row],[HY S]])/(Dashboard!$C$19+Dashboard!$C$20+Dashboard!$C$21)*100 | W6: =ROUND((Dashboard!$C$13*tblHistory[[#This Row],[NDX S]]+Dashboard!$C$14*tblHistory[[#This Row],[SOX S]]+Dashboard!$C$15*tblHistory[[#This Row],[AIQ S]]+Dashboard!$C$16*tblHistory[[#This Row],[DTCR S]]+Dashboard!$C$17*tblHistory[[#This Row],[BBB S]]+Dashboard!$C$18*tblHistory[[#This Row],[CCC S]]+Dashboard!$C$19*tblHistory[[#This Row],[BIZD S]]+Dashboard!$C$20*tblHistory[[#This Row],[BKLN S]]+Dashboard!$C$21*tblHistory[[#This Row],[HY S]])/(Dashboard!$C$13+Dashboard!$C$14+Dashboard!$C$15+Dashboard!$C$16+Dashboard!$C$17+Dashboard!$C$18+Dashboard!$C$19+Dashboard!$C$20+Dashboard!$C$21)*100,0) | X6: =IFERROR(--(tblHistory[[#This Row],[Score]]>=50),0) | Y6: =IFERROR(--AND(tblHistory[[#This Row],[Score]]>=60,OR(AND(tblHistory[[#This Row],[BIZD S]]>=0.8,tblHistory[[#This Row],[BKLN S]]>=0.5),tblHistory[[#This Row],[CCC S]]>=0.8)),0) | Z6: =IFERROR(--AND(tblHistory[[#This Row],[Score]]>=70,tblHistory[[#This Row],[SOX S]]>=0.83,tblHistory[[#This Row],[AIQ S]]>=0.8),0) | AA6: =IFERROR(--AND(tblHistory[[#This Row],[Score]]>=75,tblHistory[[#This Row],[NDX S]]=1,OR(IF(ISNUMBER(tblHistory[[#This Row],[HY]]),tblHistory[[#This Row],[HY]],SUMIFS(tblHistory[HY],tblHistory[Date],_xlfn.MAXIFS(tblHistory[Date],tblHistory[Date],"<"&tblHistory[[#This Row],[Date]],tblHistory[HY],"<>")))>=500,tblHistory[[#This Row],[BIZD S]]=1)),0) | AB6: =IFERROR(--(COUNTIFS(tblHistory[Date],">="&tblHistory[[#This Row],[Date]],tblHistory[Date],"<="&_xlfn.AGGREGATE(15,6,tblHistory[Date]/(tblHistory[Date]>=tblHistory[[#This Row],[Date]]),5),tblHistory[L1],1)=5),0) | AC6: =IFERROR(--(COUNTIFS(tblHistory[Date],">="&tblHistory[[#This Row],[Date]],tblHistory[Date],"<="&_xlfn.AGGREGATE(15,6,tblHistory[Date]/(tblHistory[Date]>=tblHistory[[#This Row],[Date]]),5),tblHistory[L2],1)=5),0) | AD6: =IFERROR(--(COUNTIFS(tblHistory[Date],">="&tblHistory[[#This Row],[Date]],tblHistory[Date],"<="&_xlfn.AGGREGATE(15,6,tblHistory[Date]/(tblHistory[Date]>=tblHistory[[#This Row],[Date]]),5),tblHistory[L3],1)=5),0) | AE6: =IFERROR(--(COUNTIFS(tblHistory[Date],">="&tblHistory[[#This Row],[Date]],tblHistory[Date],"<="&_xlfn.AGGREGATE(15,6,tblHistory[Date]/(tblHistory[Date]>=tblHistory[[#This Row],[Date]]),5),tblHistory[L4],1)=5),0)
A7: 46317 | B7: 28958.69 | C7: 10731.98 | D7: 62.07 | E7: 24.95 | F7: 111 | G7: 1340 | H7: 12.06 | I7: 20.29 | J7: 340 | K7: =IF(tblHistory[[#This Row],[Date]]-MIN(tblHistory[Date])<729,NA(),IF(IF(ISNUMBER(tblHistory[[#This Row],[NDX]]),tblHistory[[#This Row],[NDX]],SUMIFS(tblHistory[NDX],tblHistory[Date],_xlfn.MAXIFS(tblHistory[Date],tblHistory[Date],"<"&tblHistory[[#This Row],[Date]],tblHistory[NDX],"<>")))=0,0,MIN(1,MAX(0,((IF(ISNUMBER(tblHistory[[#This Row],[NDX]]),tblHistory[[#This Row],[NDX]],SUMIFS(tblHistory[NDX],tblHistory[Date],_xlfn.MAXIFS(tblHistory[Date],tblHistory[Date],"<"&tblHistory[[#This Row],[Date]],tblHistory[NDX],"<>")))/_xlfn.MAXIFS(tblHistory[NDX],tblHistory[Date],"<="&tblHistory[[#This Row],[Date]],tblHistory[Date],">="&tblHistory[[#This Row],[Date]]-730)-1)-Dashboard!$G$13)/(Dashboard!$H$13-Dashboard!$G$13))))) | L7: =IF(tblHistory[[#This Row],[Date]]-MIN(tblHistory[Date])<729,NA(),IF(IF(ISNUMBER(tblHistory[[#This Row],[SOX]]),tblHistory[[#This Row],[SOX]],SUMIFS(tblHistory[SOX],tblHistory[Date],_xlfn.MAXIFS(tblHistory[Date],tblHistory[Date],"<"&tblHistory[[#This Row],[Date]],tblHistory[SOX],"<>")))=0,0,MIN(1,MAX(0,((IF(ISNUMBER(tblHistory[[#This Row],[SOX]]),tblHistory[[#This Row],[SOX]],SUMIFS(tblHistory[SOX],tblHistory[Date],_xlfn.MAXIFS(tblHistory[Date],tblHistory[Date],"<"&tblHistory[[#This Row],[Date]],tblHistory[SOX],"<>")))/_xlfn.MAXIFS(tblHistory[SOX],tblHistory[Date],"<="&tblHistory[[#This Row],[Date]],tblHistory[Date],">="&tblHistory[[#This Row],[Date]]-730)-1)-Dashboard!$G$14)/(Dashboard!$H$14-Dashboard!$G$14))))) | M7: =IF(tblHistory[[#This Row],[Date]]-MIN(tblHistory[Date])<729,NA(),IF(IF(ISNUMBER(tblHistory[[#This Row],[AIQ]]),tblHistory[[#This Row],[AIQ]],SUMIFS(tblHistory[AIQ],tblHistory[Date],_xlfn.MAXIFS(tblHistory[Date],tblHistory[Date],"<"&tblHistory[[#This Row],[Date]],tblHistory[AIQ],"<>")))=0,0,MIN(1,MAX(0,((IF(ISNUMBER(tblHistory[[#This Row],[AIQ]]),tblHistory[[#This Row],[AIQ]],SUMIFS(tblHistory[AIQ],tblHistory[Date],_xlfn.MAXIFS(tblHistory[Date],tblHistory[Date],"<"&tblHistory[[#This Row],[Date]],tblHistory[AIQ],"<>")))/_xlfn.MAXIFS(tblHistory[AIQ],tblHistory[Date],"<="&tblHistory[[#This Row],[Date]],tblHistory[Date],">="&tblHistory[[#This Row],[Date]]-730)-1)-Dashboard!$G$15)/(Dashboard!$H$15-Dashboard!$G$15))))) | N7: =IF(tblHistory[[#This Row],[Date]]-MIN(tblHistory[Date])<729,NA(),IF(IF(ISNUMBER(tblHistory[[#This Row],[DTCR]]),tblHistory[[#This Row],[DTCR]],SUMIFS(tblHistory[DTCR],tblHistory[Date],_xlfn.MAXIFS(tblHistory[Date],tblHistory[Date],"<"&tblHistory[[#This Row],[Date]],tblHistory[DTCR],"<>")))=0,0,MIN(1,MAX(0,((IF(ISNUMBER(tblHistory[[#This Row],[DTCR]]),tblHistory[[#This Row],[DTCR]],SUMIFS(tblHistory[DTCR],tblHistory[Date],_xlfn.MAXIFS(tblHistory[Date],tblHistory[Date],"<"&tblHistory[[#This Row],[Date]],tblHistory[DTCR],"<>")))/_xlfn.MAXIFS(tblHistory[DTCR],tblHistory[Date],"<="&tblHistory[[#This Row],[Date]],tblHistory[Date],">="&tblHistory[[#This Row],[Date]]-730)-1)-Dashboard!$G$16)/(Dashboard!$H$16-Dashboard!$G$16))))) | O7: =IF(tblHistory[[#This Row],[Date]]-MIN(tblHistory[Date])<729,NA(),MAX(MIN(1,MAX(0,(IF(ISNUMBER(tblHistory[[#This Row],[BBB]]),tblHistory[[#This Row],[BBB]],SUMIFS(tblHistory[BBB],tblHistory[Date],_xlfn.MAXIFS(tblHistory[Date],tblHistory[Date],"<"&tblHistory[[#This Row],[Date]],tblHistory[BBB],"<>")))-Dashboard!$G$17)/(Dashboard!$H$17-Dashboard!$G$17))),MIN(1,MAX(0,(IF(ISNUMBER(tblHistory[[#This Row],[BBB]]),tblHistory[[#This Row],[BBB]],SUMIFS(tblHistory[BBB],tblHistory[Date],_xlfn.MAXIFS(tblHistory[Date],tblHistory[Date],"<"&tblHistory[[#This Row],[Date]],tblHistory[BBB],"<>")))-_xlfn.MINIFS(tblHistory[BBB],tblHistory[Date],"<="&tblHistory[[#This Row],[Date]],tblHistory[Date],">="&tblHistory[[#This Row],[Date]]-365)-Dashboard!$L$17)/(Dashboard!$M$17-Dashboard!$L$17))))) | P7: =IF(tblHistory[[#This Row],[Date]]-MIN(tblHistory[Date])<729,NA(),MAX(MIN(1,MAX(0,(IF(ISNUMBER(tblHistory[[#This Row],[CCC]]),tblHistory[[#This Row],[CCC]],SUMIFS(tblHistory[CCC],tblHistory[Date],_xlfn.MAXIFS(tblHistory[Date],tblHistory[Date],"<"&tblHistory[[#This Row],[Date]],tblHistory[CCC],"<>")))-Dashboard!$G$18)/(Dashboard!$H$18-Dashboard!$G$18))),MIN(1,MAX(0,(IF(ISNUMBER(tblHistory[[#This Row],[CCC]]),tblHistory[[#This Row],[CCC]],SUMIFS(tblHistory[CCC],tblHistory[Date],_xlfn.MAXIFS(tblHistory[Date],tblHistory[Date],"<"&tblHistory[[#This Row],[Date]],tblHistory[CCC],"<>")))-_xlfn.MINIFS(tblHistory[CCC],tblHistory[Date],"<="&tblHistory[[#This Row],[Date]],tblHistory[Date],">="&tblHistory[[#This Row],[Date]]-365)-Dashboard!$L$18)/(Dashboard!$M$18-Dashboard!$L$18))))) | Q7: =IF(tblHistory[[#This Row],[Date]]-MIN(tblHistory[Date])<729,NA(),IF(IF(ISNUMBER(tblHistory[[#This Row],[BIZD]]),tblHistory[[#This Row],[BIZD]],SUMIFS(tblHistory[BIZD],tblHistory[Date],_xlfn.MAXIFS(tblHistory[Date],tblHistory[Date],"<"&tblHistory[[#This Row],[Date]],tblHistory[BIZD],"<>")))=0,0,MIN(1,MAX(0,((IF(ISNUMBER(tblHistory[[#This Row],[BIZD]]),tblHistory[[#This Row],[BIZD]],SUMIFS(tblHistory[BIZD],tblHistory[Date],_xlfn.MAXIFS(tblHistory[Date],tblHistory[Date],"<"&tblHistory[[#This Row],[Date]],tblHistory[BIZD],"<>")))/_xlfn.MAXIFS(tblHistory[BIZD],tblHistory[Date],"<="&tblHistory[[#This Row],[Date]],tblHistory[Date],">="&tblHistory[[#This Row],[Date]]-730)-1)-Dashboard!$G$19)/(Dashboard!$H$19-Dashboard!$G$19))))) | R7: =IF(tblHistory[[#This Row],[Date]]-MIN(tblHistory[Date])<729,NA(),IF(IF(ISNUMBER(tblHistory[[#This Row],[BKLN]]),tblHistory[[#This Row],[BKLN]],SUMIFS(tblHistory[BKLN],tblHistory[Date],_xlfn.MAXIFS(tblHistory[Date],tblHistory[Date],"<"&tblHistory[[#This Row],[Date]],tblHistory[BKLN],"<>")))=0,0,MIN(1,MAX(0,((IF(ISNUMBER(tblHistory[[#This Row],[BKLN]]),tblHistory[[#This Row],[BKLN]],SUMIFS(tblHistory[BKLN],tblHistory[Date],_xlfn.MAXIFS(tblHistory[Date],tblHistory[Date],"<"&tblHistory[[#This Row],[Date]],tblHistory[BKLN],"<>")))/_xlfn.MAXIFS(tblHistory[BKLN],tblHistory[Date],"<="&tblHistory[[#This Row],[Date]],tblHistory[Date],">="&tblHistory[[#This Row],[Date]]-730)-1)-Dashboard!$G$20)/(Dashboard!$H$20-Dashboard!$G$20))))) | S7: =IF(tblHistory[[#This Row],[Date]]-MIN(tblHistory[Date])<729,NA(),MAX(MIN(1,MAX(0,(IF(ISNUMBER(tblHistory[[#This Row],[HY]]),tblHistory[[#This Row],[HY]],SUMIFS(tblHistory[HY],tblHistory[Date],_xlfn.MAXIFS(tblHistory[Date],tblHistory[Date],"<"&tblHistory[[#This Row],[Date]],tblHistory[HY],"<>")))-Dashboard!$G$21)/(Dashboard!$H$21-Dashboard!$G$21))),MIN(1,MAX(0,(IF(ISNUMBER(tblHistory[[#This Row],[HY]]),tblHistory[[#This Row],[HY]],SUMIFS(tblHistory[HY],tblHistory[Date],_xlfn.MAXIFS(tblHistory[Date],tblHistory[Date],"<"&tblHistory[[#This Row],[Date]],tblHistory[HY],"<>")))-_xlfn.MINIFS(tblHistory[HY],tblHistory[Date],"<="&tblHistory[[#This Row],[Date]],tblHistory[Date],">="&tblHistory[[#This Row],[Date]]-365)-Dashboard!$L$21)/(Dashboard!$M$21-Dashboard!$L$21))))) | T7: =(Dashboard!$C$13*tblHistory[[#This Row],[NDX S]]+Dashboard!$C$14*tblHistory[[#This Row],[SOX S]]+Dashboard!$C$15*tblHistory[[#This Row],[AIQ S]])/(Dashboard!$C$13+Dashboard!$C$14+Dashboard!$C$15)*100 | U7: =(Dashboard!$C$16*tblHistory[[#This Row],[DTCR S]]+Dashboard!$C$17*tblHistory[[#This Row],[BBB S]]+Dashboard!$C$18*tblHistory[[#This Row],[CCC S]])/(Dashboard!$C$16+Dashboard!$C$17+Dashboard!$C$18)*100 | V7: =(Dashboard!$C$19*tblHistory[[#This Row],[BIZD S]]+Dashboard!$C$20*tblHistory[[#This Row],[BKLN S]]+Dashboard!$C$21*tblHistory[[#This Row],[HY S]])/(Dashboard!$C$19+Dashboard!$C$20+Dashboard!$C$21)*100 | W7: =ROUND((Dashboard!$C$13*tblHistory[[#This Row],[NDX S]]+Dashboard!$C$14*tblHistory[[#This Row],[SOX S]]+Dashboard!$C$15*tblHistory[[#This Row],[AIQ S]]+Dashboard!$C$16*tblHistory[[#This Row],[DTCR S]]+Dashboard!$C$17*tblHistory[[#This Row],[BBB S]]+Dashboard!$C$18*tblHistory[[#This Row],[CCC S]]+Dashboard!$C$19*tblHistory[[#This Row],[BIZD S]]+Dashboard!$C$20*tblHistory[[#This Row],[BKLN S]]+Dashboard!$C$21*tblHistory[[#This Row],[HY S]])/(Dashboard!$C$13+Dashboard!$C$14+Dashboard!$C$15+Dashboard!$C$16+Dashboard!$C$17+Dashboard!$C$18+Dashboard!$C$19+Dashboard!$C$20+Dashboard!$C$21)*100,0) | X7: =IFERROR(--(tblHistory[[#This Row],[Score]]>=50),0) | Y7: =IFERROR(--AND(tblHistory[[#This Row],[Score]]>=60,OR(AND(tblHistory[[#This Row],[BIZD S]]>=0.8,tblHistory[[#This Row],[BKLN S]]>=0.5),tblHistory[[#This Row],[CCC S]]>=0.8)),0) | Z7: =IFERROR(--AND(tblHistory[[#This Row],[Score]]>=70,tblHistory[[#This Row],[SOX S]]>=0.83,tblHistory[[#This Row],[AIQ S]]>=0.8),0) | AA7: =IFERROR(--AND(tblHistory[[#This Row],[Score]]>=75,tblHistory[[#This Row],[NDX S]]=1,OR(IF(ISNUMBER(tblHistory[[#This Row],[HY]]),tblHistory[[#This Row],[HY]],SUMIFS(tblHistory[HY],tblHistory[Date],_xlfn.MAXIFS(tblHistory[Date],tblHistory[Date],"<"&tblHistory[[#This Row],[Date]],tblHistory[HY],"<>")))>=500,tblHistory[[#This Row],[BIZD S]]=1)),0) | AB7: =IFERROR(--(COUNTIFS(tblHistory[Date],">="&tblHistory[[#This Row],[Date]],tblHistory[Date],"<="&_xlfn.AGGREGATE(15,6,tblHistory[Date]/(tblHistory[Date]>=tblHistory[[#This Row],[Date]]),5),tblHistory[L1],1)=5),0) | AC7: =IFERROR(--(COUNTIFS(tblHistory[Date],">="&tblHistory[[#This Row],[Date]],tblHistory[Date],"<="&_xlfn.AGGREGATE(15,6,tblHistory[Date]/(tblHistory[Date]>=tblHistory[[#This Row],[Date]]),5),tblHistory[L2],1)=5),0) | AD7: =IFERROR(--(COUNTIFS(tblHistory[Date],">="&tblHistory[[#This Row],[Date]],tblHistory[Date],"<="&_xlfn.AGGREGATE(15,6,tblHistory[Date]/(tblHistory[Date]>=tblHistory[[#This Row],[Date]]),5),tblHistory[L3],1)=5),0) | AE7: =IFERROR(--(COUNTIFS(tblHistory[Date],">="&tblHistory[[#This Row],[Date]],tblHistory[Date],"<="&_xlfn.AGGREGATE(15,6,tblHistory[Date]/(tblHistory[Date]>=tblHistory[[#This Row],[Date]]),5),tblHistory[L4],1)=5),0)
A8: 46316 | B8: 29822.519 | C8: 11505.56 | D8: 64 | E8: 25.61 | F8: 109 | G8: 1307 | H8: 11.79 | I8: 20.32 | J8: 327 | K8: =IF(tblHistory[[#This Row],[Date]]-MIN(tblHistory[Date])<729,NA(),IF(IF(ISNUMBER(tblHistory[[#This Row],[NDX]]),tblHistory[[#This Row],[NDX]],SUMIFS(tblHistory[NDX],tblHistory[Date],_xlfn.MAXIFS(tblHistory[Date],tblHistory[Date],"<"&tblHistory[[#This Row],[Date]],tblHistory[NDX],"<>")))=0,0,MIN(1,MAX(0,((IF(ISNUMBER(tblHistory[[#This Row],[NDX]]),tblHistory[[#This Row],[NDX]],SUMIFS(tblHistory[NDX],tblHistory[Date],_xlfn.MAXIFS(tblHistory[Date],tblHistory[Date],"<"&tblHistory[[#This Row],[Date]],tblHistory[NDX],"<>")))/_xlfn.MAXIFS(tblHistory[NDX],tblHistory[Date],"<="&tblHistory[[#This Row],[Date]],tblHistory[Date],">="&tblHistory[[#This Row],[Date]]-730)-1)-Dashboard!$G$13)/(Dashboard!$H$13-Dashboard!$G$13))))) | L8: =IF(tblHistory[[#This Row],[Date]]-MIN(tblHistory[Date])<729,NA(),IF(IF(ISNUMBER(tblHistory[[#This Row],[SOX]]),tblHistory[[#This Row],[SOX]],SUMIFS(tblHistory[SOX],tblHistory[Date],_xlfn.MAXIFS(tblHistory[Date],tblHistory[Date],"<"&tblHistory[[#This Row],[Date]],tblHistory[SOX],"<>")))=0,0,MIN(1,MAX(0,((IF(ISNUMBER(tblHistory[[#This Row],[SOX]]),tblHistory[[#This Row],[SOX]],SUMIFS(tblHistory[SOX],tblHistory[Date],_xlfn.MAXIFS(tblHistory[Date],tblHistory[Date],"<"&tblHistory[[#This Row],[Date]],tblHistory[SOX],"<>")))/_xlfn.MAXIFS(tblHistory[SOX],tblHistory[Date],"<="&tblHistory[[#This Row],[Date]],tblHistory[Date],">="&tblHistory[[#This Row],[Date]]-730)-1)-Dashboard!$G$14)/(Dashboard!$H$14-Dashboard!$G$14))))) | M8: =IF(tblHistory[[#This Row],[Date]]-MIN(tblHistory[Date])<729,NA(),IF(IF(ISNUMBER(tblHistory[[#This Row],[AIQ]]),tblHistory[[#This Row],[AIQ]],SUMIFS(tblHistory[AIQ],tblHistory[Date],_xlfn.MAXIFS(tblHistory[Date],tblHistory[Date],"<"&tblHistory[[#This Row],[Date]],tblHistory[AIQ],"<>")))=0,0,MIN(1,MAX(0,((IF(ISNUMBER(tblHistory[[#This Row],[AIQ]]),tblHistory[[#This Row],[AIQ]],SUMIFS(tblHistory[AIQ],tblHistory[Date],_xlfn.MAXIFS(tblHistory[Date],tblHistory[Date],"<"&tblHistory[[#This Row],[Date]],tblHistory[AIQ],"<>")))/_xlfn.MAXIFS(tblHistory[AIQ],tblHistory[Date],"<="&tblHistory[[#This Row],[Date]],tblHistory[Date],">="&tblHistory[[#This Row],[Date]]-730)-1)-Dashboard!$G$15)/(Dashboard!$H$15-Dashboard!$G$15))))) | N8: =IF(tblHistory[[#This Row],[Date]]-MIN(tblHistory[Date])<729,NA(),IF(IF(ISNUMBER(tblHistory[[#This Row],[DTCR]]),tblHistory[[#This Row],[DTCR]],SUMIFS(tblHistory[DTCR],tblHistory[Date],_xlfn.MAXIFS(tblHistory[Date],tblHistory[Date],"<"&tblHistory[[#This Row],[Date]],tblHistory[DTCR],"<>")))=0,0,MIN(1,MAX(0,((IF(ISNUMBER(tblHistory[[#This Row],[DTCR]]),tblHistory[[#This Row],[DTCR]],SUMIFS(tblHistory[DTCR],tblHistory[Date],_xlfn.MAXIFS(tblHistory[Date],tblHistory[Date],"<"&tblHistory[[#This Row],[Date]],tblHistory[DTCR],"<>")))/_xlfn.MAXIFS(tblHistory[DTCR],tblHistory[Date],"<="&tblHistory[[#This Row],[Date]],tblHistory[Date],">="&tblHistory[[#This Row],[Date]]-730)-1)-Dashboard!$G$16)/(Dashboard!$H$16-Dashboard!$G$16))))) | O8: =IF(tblHistory[[#This Row],[Date]]-MIN(tblHistory[Date])<729,NA(),MAX(MIN(1,MAX(0,(IF(ISNUMBER(tblHistory[[#This Row],[BBB]]),tblHistory[[#This Row],[BBB]],SUMIFS(tblHistory[BBB],tblHistory[Date],_xlfn.MAXIFS(tblHistory[Date],tblHistory[Date],"<"&tblHistory[[#This Row],[Date]],tblHistory[BBB],"<>")))-Dashboard!$G$17)/(Dashboard!$H$17-Dashboard!$G$17))),MIN(1,MAX(0,(IF(ISNUMBER(tblHistory[[#This Row],[BBB]]),tblHistory[[#This Row],[BBB]],SUMIFS(tblHistory[BBB],tblHistory[Date],_xlfn.MAXIFS(tblHistory[Date],tblHistory[Date],"<"&tblHistory[[#This Row],[Date]],tblHistory[BBB],"<>")))-_xlfn.MINIFS(tblHistory[BBB],tblHistory[Date],"<="&tblHistory[[#This Row],[Date]],tblHistory[Date],">="&tblHistory[[#This Row],[Date]]-365)-Dashboard!$L$17)/(Dashboard!$M$17-Dashboard!$L$17))))) | P8: =IF(tblHistory[[#This Row],[Date]]-MIN(tblHistory[Date])<729,NA(),MAX(MIN(1,MAX(0,(IF(ISNUMBER(tblHistory[[#This Row],[CCC]]),tblHistory[[#This Row],[CCC]],SUMIFS(tblHistory[CCC],tblHistory[Date],_xlfn.MAXIFS(tblHistory[Date],tblHistory[Date],"<"&tblHistory[[#This Row],[Date]],tblHistory[CCC],"<>")))-Dashboard!$G$18)/(Dashboard!$H$18-Dashboard!$G$18))),MIN(1,MAX(0,(IF(ISNUMBER(tblHistory[[#This Row],[CCC]]),tblHistory[[#This Row],[CCC]],SUMIFS(tblHistory[CCC],tblHistory[Date],_xlfn.MAXIFS(tblHistory[Date],tblHistory[Date],"<"&tblHistory[[#This Row],[Date]],tblHistory[CCC],"<>")))-_xlfn.MINIFS(tblHistory[CCC],tblHistory[Date],"<="&tblHistory[[#This Row],[Date]],tblHistory[Date],">="&tblHistory[[#This Row],[Date]]-365)-Dashboard!$L$18)/(Dashboard!$M$18-Dashboard!$L$18))))) | Q8: =IF(tblHistory[[#This Row],[Date]]-MIN(tblHistory[Date])<729,NA(),IF(IF(ISNUMBER(tblHistory[[#This Row],[BIZD]]),tblHistory[[#This Row],[BIZD]],SUMIFS(tblHistory[BIZD],tblHistory[Date],_xlfn.MAXIFS(tblHistory[Date],tblHistory[Date],"<"&tblHistory[[#This Row],[Date]],tblHistory[BIZD],"<>")))=0,0,MIN(1,MAX(0,((IF(ISNUMBER(tblHistory[[#This Row],[BIZD]]),tblHistory[[#This Row],[BIZD]],SUMIFS(tblHistory[BIZD],tblHistory[Date],_xlfn.MAXIFS(tblHistory[Date],tblHistory[Date],"<"&tblHistory[[#This Row],[Date]],tblHistory[BIZD],"<>")))/_xlfn.MAXIFS(tblHistory[BIZD],tblHistory[Date],"<="&tblHistory[[#This Row],[Date]],tblHistory[Date],">="&tblHistory[[#This Row],[Date]]-730)-1)-Dashboard!$G$19)/(Dashboard!$H$19-Dashboard!$G$19))))) | R8: =IF(tblHistory[[#This Row],[Date]]-MIN(tblHistory[Date])<729,NA(),IF(IF(ISNUMBER(tblHistory[[#This Row],[BKLN]]),tblHistory[[#This Row],[BKLN]],SUMIFS(tblHistory[BKLN],tblHistory[Date],_xlfn.MAXIFS(tblHistory[Date],tblHistory[Date],"<"&tblHistory[[#This Row],[Date]],tblHistory[BKLN],"<>")))=0,0,MIN(1,MAX(0,((IF(ISNUMBER(tblHistory[[#This Row],[BKLN]]),tblHistory[[#This Row],[BKLN]],SUMIFS(tblHistory[BKLN],tblHistory[Date],_xlfn.MAXIFS(tblHistory[Date],tblHistory[Date],"<"&tblHistory[[#This Row],[Date]],tblHistory[BKLN],"<>")))/_xlfn.MAXIFS(tblHistory[BKLN],tblHistory[Date],"<="&tblHistory[[#This Row],[Date]],tblHistory[Date],">="&tblHistory[[#This Row],[Date]]-730)-1)-Dashboard!$G$20)/(Dashboard!$H$20-Dashboard!$G$20))))) | S8: =IF(tblHistory[[#This Row],[Date]]-MIN(tblHistory[Date])<729,NA(),MAX(MIN(1,MAX(0,(IF(ISNUMBER(tblHistory[[#This Row],[HY]]),tblHistory[[#This Row],[HY]],SUMIFS(tblHistory[HY],tblHistory[Date],_xlfn.MAXIFS(tblHistory[Date],tblHistory[Date],"<"&tblHistory[[#This Row],[Date]],tblHistory[HY],"<>")))-Dashboard!$G$21)/(Dashboard!$H$21-Dashboard!$G$21))),MIN(1,MAX(0,(IF(ISNUMBER(tblHistory[[#This Row],[HY]]),tblHistory[[#This Row],[HY]],SUMIFS(tblHistory[HY],tblHistory[Date],_xlfn.MAXIFS(tblHistory[Date],tblHistory[Date],"<"&tblHistory[[#This Row],[Date]],tblHistory[HY],"<>")))-_xlfn.MINIFS(tblHistory[HY],tblHistory[Date],"<="&tblHistory[[#This Row],[Date]],tblHistory[Date],">="&tblHistory[[#This Row],[Date]]-365)-Dashboard!$L$21)/(Dashboard!$M$21-Dashboard!$L$21))))) | T8: =(Dashboard!$C$13*tblHistory[[#This Row],[NDX S]]+Dashboard!$C$14*tblHistory[[#This Row],[SOX S]]+Dashboard!$C$15*tblHistory[[#This Row],[AIQ S]])/(Dashboard!$C$13+Dashboard!$C$14+Dashboard!$C$15)*100 | U8: =(Dashboard!$C$16*tblHistory[[#This Row],[DTCR S]]+Dashboard!$C$17*tblHistory[[#This Row],[BBB S]]+Dashboard!$C$18*tblHistory[[#This Row],[CCC S]])/(Dashboard!$C$16+Dashboard!$C$17+Dashboard!$C$18)*100 | V8: =(Dashboard!$C$19*tblHistory[[#This Row],[BIZD S]]+Dashboard!$C$20*tblHistory[[#This Row],[BKLN S]]+Dashboard!$C$21*tblHistory[[#This Row],[HY S]])/(Dashboard!$C$19+Dashboard!$C$20+Dashboard!$C$21)*100 | W8: =ROUND((Dashboard!$C$13*tblHistory[[#This Row],[NDX S]]+Dashboard!$C$14*tblHistory[[#This Row],[SOX S]]+Dashboard!$C$15*tblHistory[[#This Row],[AIQ S]]+Dashboard!$C$16*tblHistory[[#This Row],[DTCR S]]+Dashboard!$C$17*tblHistory[[#This Row],[BBB S]]+Dashboard!$C$18*tblHistory[[#This Row],[CCC S]]+Dashboard!$C$19*tblHistory[[#This Row],[BIZD S]]+Dashboard!$C$20*tblHistory[[#This Row],[BKLN S]]+Dashboard!$C$21*tblHistory[[#This Row],[HY S]])/(Dashboard!$C$13+Dashboard!$C$14+Dashboard!$C$15+Dashboard!$C$16+Dashboard!$C$17+Dashboard!$C$18+Dashboard!$C$19+Dashboard!$C$20+Dashboard!$C$21)*100,0) | X8: =IFERROR(--(tblHistory[[#This Row],[Score]]>=50),0) | Y8: =IFERROR(--AND(tblHistory[[#This Row],[Score]]>=60,OR(AND(tblHistory[[#This Row],[BIZD S]]>=0.8,tblHistory[[#This Row],[BKLN S]]>=0.5),tblHistory[[#This Row],[CCC S]]>=0.8)),0) | Z8: =IFERROR(--AND(tblHistory[[#This Row],[Score]]>=70,tblHistory[[#This Row],[SOX S]]>=0.83,tblHistory[[#This Row],[AIQ S]]>=0.8),0) | AA8: =IFERROR(--AND(tblHistory[[#This Row],[Score]]>=75,tblHistory[[#This Row],[NDX S]]=1,OR(IF(ISNUMBER(tblHistory[[#This Row],[HY]]),tblHistory[[#This Row],[HY]],SUMIFS(tblHistory[HY],tblHistory[Date],_xlfn.MAXIFS(tblHistory[Date],tblHistory[Date],"<"&tblHistory[[#This Row],[Date]],tblHistory[HY],"<>")))>=500,tblHistory[[#This Row],[BIZD S]]=1)),0) | AB8: =IFERROR(--(COUNTIFS(tblHistory[Date],">="&tblHistory[[#This Row],[Date]],tblHistory[Date],"<="&_xlfn.AGGREGATE(15,6,tblHistory[Date]/(tblHistory[Date]>=tblHistory[[#This Row],[Date]]),5),tblHistory[L1],1)=5),0) | AC8: =IFERROR(--(COUNTIFS(tblHistory[Date],">="&tblHistory[[#This Row],[Date]],tblHistory[Date],"<="&_xlfn.AGGREGATE(15,6,tblHistory[Date]/(tblHistory[Date]>=tblHistory[[#This Row],[Date]]),5),tblHistory[L2],1)=5),0) | AD8: =IFERROR(--(COUNTIFS(tblHistory[Date],">="&tblHistory[[#This Row],[Date]],tblHistory[Date],"<="&_xlfn.AGGREGATE(15,6,tblHistory[Date]/(tblHistory[Date]>=tblHistory[[#This Row],[Date]]),5),tblHistory[L3],1)=5),0) | AE8: =IFERROR(--(COUNTIFS(tblHistory[Date],">="&tblHistory[[#This Row],[Date]],tblHistory[Date],"<="&_xlfn.AGGREGATE(15,6,tblHistory[Date]/(tblHistory[Date]>=tblHistory[[#This Row],[Date]]),5),tblHistory[L4],1)=5),0)
